Workbook

Sheet Start Here
A1: Domain Investing — Rubric & Portfolio Tracker
A4: HOW TO USE THIS FILE
A5: 1. Assumptions | B5: Set your commission rate, sell-through rate and holding horizon FIRST. Every max-bid and break-even number in the file is driven off this tab.
A6: 2. Rubric | B6: Read the scoring definitions. Adjust the six weights if you disagree — they must sum to 100%. The Weight Check cell turns red if they don't.
A7: 3. Candidates | B7: One row per name you are considering. Score the five manual criteria 1-5, enter your acquisition cost and honest resale estimate. The sheet returns a weighted score, a max rational bid, and a verdict.
A8: 4. Portfolio | B8: One row per name you actually own. Tracks cumulative renewal carry and the list price you need to break even after commission.
A9: 5. Sales Log | B9: One row per sale. Feeds realised P&L and your true sell-through rate.
A10: 6. Dashboard | B10: Read-only summary. The number to watch is Annual Renewal Burden vs. Realised Net Profit.
A11: 7. Comps | B11: Reference sales and market benchmarks with sources, for calibrating the Comp Support score.
A12: 8. Market Frequency | B12: How often domains actually sell and for how much, with the derivation behind the sell-through rate and a calibrator that turns a break-even into a percentile.
A13: 9. Closeout Screener | B13: Expired names in GoDaddy's $11-to-$5 closeout window. Scores name quality and asset quality separately, then gives bid timing.
A15: COLOUR LEGEND
A16: Blue text | B16: You type here. These are inputs.
A17: Yellow fill | B17: Key assumption — the numbers most worth arguing about.
A18: Black text | B18: Formula. Do not overwrite.
A19: Green text | B19: Formula that pulls from another sheet. Do not overwrite.
A20: Orange row | B20: EXAMPLE ROW showing the expected format. Delete it before you start.
A22: THE ONE THING TO REMEMBER
A23: Carry kills portfolios | B23: At a 1% sell-through rate you sell roughly one name per hundred per year, while paying renewals on all hundred. A name is only worth owning if its expected net proceeds beat its expected carry over your holding horizon. That comparison is the Max Rational Bid column on the Candidates tab — if your acquisition cost is above it, the name loses money on average no matter how good it sounds.
A24: Availability | B24: This file does not check whether a domain is registered. Column A holds the full domain, so select it, copy, and paste straight into GoDaddy's bulk search (up to 500 at a time), then mark the result in the Availability column. The Ext column derives itself from column A — do not type into it.
A25: Appraisals | B25: GoDaddy's automated appraisal is not evidence. Use the Comp Support score instead — it asks whether comparable names have actually sold, which is the only valuation signal with a buyer behind it.
A27: Built | B27: 2026-08-06. Market benchmarks on the Comps tab are as-published; re-check before relying on them.

Sheet Assumptions
A1: Assumptions — set these before anything else
A3: Assumption | B3: Value | C3: Unit | D3: Why it matters / source
A4: Commission rate on sale | B4: 0.2 | C4: % | D4: Afternic/GoDaddy: 30% on Boost, 25% Basic; drops to 20% (Boost) or 15% (Basic) if you point the domain at GoDaddy aftermarket nameservers. 20% assumes Boost + GD nameservers.
A5: Minimum commission per sale | B5: 15 | C5: USD | D5: GoDaddy applies a $15 floor. Only bites on sub-$100 sales.
A6: Expected sell-through rate (per year) | B6: 0.01 | C6: % | D6: DERIVED, see the Market Frequency tab. About 256,600 reported sales a year above $100 against 20m+ listings on Afternic alone gives 1.28%; against 25-30m unique listings across venues it is 0.86-1.03%. 1.00% is the middle of that. The commonly quoted 1.5-2% is measured on curated portfolios or is simply optimistic - assuming you beat the market before you have evidence is the same error as guessing a resale value. Raise it only when your own Sales Log earns it.
A7: Holding horizon (years) | B7: 5 | C7: years | D7: Typical time-to-sale for ordinary inventory is 5-10 years. This is the window the max-bid maths assumes you are willing to fund renewals for.
A8: Default annual renewal — .com | B8: 11 | C8: USD | D8: Typical .com renewal. Override per name where different.
A9: Default annual renewal — premium TLD | B9: 35 | C9: USD | D9: .ai/.io renewals run far higher and are the main reason trendy-TLD portfolios lose money at low sell-through rates.
A10: Required return multiple on cost | B10: 10 | C10: x | D10: Minimum sale-price-to-acquisition-cost ratio you will accept, used to set target list prices. 10x on a $12 hand-reg is a $120 name — set this high, most names never sell at all.
A11: Quality pivot score (neutral) | B11: 3 | C11: years | D11: A name scoring exactly this gets the base sell-through rate above. Better names get a higher rate, worse names a lower one.
A12: Quality sensitivity (0 = off) | B12: 1 | C12: years | D12: MODELLING ASSUMPTION, NOT MEASURED DATA. Effective rate = base rate x (score / pivot) ^ this. At 1.0 the relationship is linear: a 4.5 name is assumed to sell 1.5x as often as a 3.0 name. Set to 0 to disable and give every name the same probability — which is what the first version of this model did, and it was wrong, because it made name quality irrelevant to the economics.
A13: Safety multiple required for BUY | B13: 2 | C13: x | D13: How far above break-even a valuation must sit before the verdict is BUY. At 2.0 the name must be worth twice what the maths strictly requires — headroom for the valuation being wrong.
A15: DERIVED — do not edit
A16: Probability a listed name sells within the horizon | B16: =1-(1-$B$6)^$B$7 -> 0.04900995 | D16: 1 minus the chance it fails to sell every year running. This single number is why most portfolios lose money: over 5 years at a 2% annual rate, roughly 9 names in 10 do not sell at all.
A17: Expected renewal carry per name over horizon (.com) | B17: =$B$8*$B$7 -> 55 | D17: What you pay to keep one .com alive for the full horizon, win or lose.

Sheet Rubric
A1: Scoring Rubric — six weighted criteria, scored 1 to 5
A3: Weights drive the Candidates tab. Edit the blue cells if you disagree; they must sum to 100%.
A4: Criterion | B4: Weight | C4: Score 1 — avoid | D4: Score 3 — marginal | E4: Score 5 — strong
A5: Extension | B5: 0.22 | C5: New gTLD (.shop, .xyz, .link) or an obscure ccTLD. Supply is about to expand further when ICANN reopens the new-gTLD window. | D5: .co, .net, .org, or a strong country ccTLD. Sells, but at a fraction of .com. | E5: .com. Every one of 2026's largest sales was a .com. .ai is a genuine second tier for AI-native buyers but carries a much higher renewal.
A6: Commercial intent | B6: 0.3 | C6: Hobby, meme, or personal-interest term. Nobody monetises it, so nobody bids. | D6: Real commercial term, but low customer value or a thin buyer pool. | E6: Term in a sector where one customer is worth thousands — finance, insurance, legal, medical, real estate, B2B SaaS. A $3k domain is a rounding error to that buyer.
A7: Comp support | B7: 0.22 | C7: No comparable sale you can point to. You are guessing. | D7: Loosely similar names have sold, but at scattered prices or years ago. | E7: Several closely comparable names sold recently at prices you can cite. This is the only valuation input with an actual buyer behind it.
A8: Length & memorability | B8: 0.16 | C8: Four or more words, over ~20 characters, or a forgettable string. | D8: Two or three words, reasonable length, unremarkable. | E8: One strong dictionary word, or a tight two-word pairing. Short 4-5 character .com remains the most valuable class there is.
A9: Radio test | B9: 0.1 | C9: Has to be spelled out. Homophone traps, doubled letters, invented spellings. | D9: Mostly clear, occasional spelling correction needed. | E9: Say it once on a phone call and the other person types it correctly.
A10: Weight check | B10: =SUM(B5:B9) -> 1 | C10: =IF(ABS(B10-1)<0.0001,"OK — weights sum to 100%","ERROR — weights must sum to 100%") -> OK — weights sum to 100%
A12: EXTENSION LOOKUP — used automatically by the Candidates tab
A13: Extension | B13: Score | C13: Typical annual renewal | D13: Note
A14: com | B14: 5 | C14: 11 | D14: The default. Dominates every top-sales chart.
A15: ai | B15: 4 | C15: 90 | D15: Real demand, premium resale averages around $6.5k — but the renewal is the trap.
A16: io | B16: 3 | C16: 40 | D16: Startup-friendly, high renewal, softening as .ai takes the tech mindshare.
A17: co | B17: 3 | C17: 30 | D17: Credible .com alternative, sells at a steep discount to it.
A18: net | B18: 3 | C18: 13 | D18: Old and trusted, limited upside.
A19: org | B19: 3 | C19: 13 | D19: Strong for nonprofit/institutional buyers, narrow otherwise.
A20: app | B20: 2 | C20: 18 | D20: Niche, mostly end-user rather than investor demand.
A21: dev | B21: 2 | C21: 15 | D21: Same — developer tools, thin aftermarket.
A22: xyz | B22: 1 | C22: 12 | D22: High volume, low realised prices.
A23: other | B23: 1 | C23: 25 | D23: Default for anything unlisted. Assume the market is thin.
A25: HARD FILTERS — any one of these rejects the name regardless of score
A26: REJECT if: | B26: Trademark risk — contains or closely mimics an existing brand. A UDRP complaint costs you the name and the legal fee, and intent to resell is exactly what the process punishes.
A27: REJECT if: | B27: Contains a hyphen or a digit. Both collapse resale value and fail the radio test.
A28: REJECT if: | B28: Four or more words.
A29: REJECT if: | B29: Plural/singular confusion with an established site you would be trading off.
A31: VERDICT THRESHOLDS
A32: Verdict | B32: Condition | C32: Meaning
A33: BUY | B33: Score >= 4.00 and cost <= max rational bid | C33: Passes both the quality bar and the maths.
A34: BUY IF CHEAPER | B34: Score >= 4.00 but cost > max rational bid | C34: Good name, wrong price. Bid the max rational bid and walk if it goes higher.
A35: WATCH | B35: Score 3.20 - 3.99 | C35: Borderline. Only take it at a low acquisition cost.
A36: PASS | B36: Score < 3.20 | C36: Below the bar.
A37: REJECT | B37: Any hard filter failed | C37: Do not buy at any price.

Sheet Candidates
A1: Candidate Pipeline — names under consideration
A2: Rows 5-112: equipment finance, checked 2026-08-03 — a mature niche, nothing clearing. Rows 113+: batch 3, emerging categories researched 2026-08-04 (agentic AI, GEO/AEO, slop provenance, longevity, creator economy) plus three viral-slang controls. Est. Resale Value stays EMPTY until you have a sourced number; work from BREAK-EVEN RESALE, which needs no estimate.
A4: Domain (full, e.g. name.com) | B4: Ext | C4: Ext Score | D4: Commercial Intent (1-5) | E4: Comp Support (1-5) | F4: Length & Memorability (1-5) | G4: Radio Test (1-5) | H4: TM Risk? (Y/N) | I4: Hyphen/Digit? (Y/N) | J4: Acquisition Cost | K4: Est. Resale Value | L4: Valuation Source | M4: Annual Renewal | N4: Weighted Score | O4: Hard Filter | P4: Effective STR /yr | Q4: P(sale in horizon) | R4: Expected Carry | S4: BREAK-EVEN RESALE | T4: Value Ratio | U4: Max Rational Bid | V4: Verdict | W4: Availability | X4: Notes
A5: workingcapital.com | B5: =IF($A5="","",IF(ISERROR(FIND(".",$A5)),"",LOWER(MID($A5,FIND(CHAR(1),SUBSTITUTE($A5,".",CHAR(1),LEN($A5)-LEN(SUBSTITUTE($A5,".",""))))+1,LEN($A5))))) -> com | C5: =IF($B5="","",IFERROR(INDEX(Rubric!$B$14:$B$23,MATCH($B5,Rubric!$A$14:$A$23,0)),INDEX(Rubric!$B$14:$B$23,MATCH("other",Rubric!$A$14:$A$23,0)))) -> 5 | D5: 5 | E5: 4 | F5: 4 | G5: 5 | H5: N | I5: N | M5: =IF($B5="","",IFERROR(INDEX(Rubric!$C$14:$C$23,MATCH($B5,Rubric!$A$14:$A$23,0)),INDEX(Rubric!$C$14:$C$23,MATCH("other",Rubric!$A$14:$A$23,0)))) -> 11 | N5: =IF(OR($A5="",$C5=""),"",$C5*Rubric!$B$5+$D5*Rubric!$B$6+$E5*Rubric!$B$7+$F5*Rubric!$B$8+$G5*Rubric!$B$9) -> 4.62 | O5: =IF($A5="","",IF(OR(UPPER($H5)="Y",UPPER($I5)="Y"),"FAIL","PASS")) -> PASS | P5: =IF($N5="","",Assumptions!$B$6*MAX(0.05,($N5/Assumptions!$B$11)^Assumptions!$B$12)) -> 0.0154 | Q5: =IF($P5="","",1-(1-$P5)^Assumptions!$B$7) -> 0.074664642 | R5: =IF($M5="","",$M5*Assumptions!$B$7) -> 55 | S5: =IF(OR($J5="",$Q5="",$Q5=0),"",($J5+$R5)/($Q5*(1-Assumptions!$B$4))) | T5: =IF(OR($K5="",$S5="",$S5=0),"",$K5/$S5) | U5: =IF(OR($K5="",$Q5=""),"",MAX(0,($K5-MAX($K5*Assumptions!$B$4,Assumptions!$B$5))*$Q5-$R5)) | V5: =IF($A5="","",IF($O5="FAIL","REJECT",IF($J5="","NEEDS PRICE",IF(OR($K5="",$L5=""),"NEEDS VALUATION",IF($T5>=Assumptions!$B$13,"BUY",IF($T5>=1,"MARGINAL","PASS")))))) -> NEEDS PRICE | W5: Taken | X5: [T1] Core term, huge buyer pool. Certainly registered — auction/broker target only.
A6: commerciallending.com | B6: =IF($A6="","",IF(ISERROR(FIND(".",$A6)),"",LOWER(MID($A6,FIND(CHAR(1),SUBSTITUTE($A6,".",CHAR(1),LEN($A6)-LEN(SUBSTITUTE($A6,".",""))))+1,LEN($A6))))) -> com | C6: =IF($B6="","",IFERROR(INDEX(Rubric!$B$14:$B$23,MATCH($B6,Rubric!$A$14:$A$23,0)),INDEX(Rubric!$B$14:$B$23,MATCH("other",Rubric!$A$14:$A$23,0)))) -> 5 | D6: 5 | E6: 3 | F6: 3 | G6: 4 | H6: N | I6: N | M6: =IF($B6="","",IFERROR(INDEX(Rubric!$C$14:$C$23,MATCH($B6,Rubric!$A$14:$A$23,0)),INDEX(Rubric!$C$14:$C$23,MATCH("other",Rubric!$A$14:$A$23,0)))) -> 11 | N6: =IF(OR($A6="",$C6=""),"",$C6*Rubric!$B$5+$D6*Rubric!$B$6+$E6*Rubric!$B$7+$F6*Rubric!$B$8+$G6*Rubric!$B$9) -> 4.14 | O6: =IF($A6="","",IF(OR(UPPER($H6)="Y",UPPER($I6)="Y"),"FAIL","PASS")) -> PASS | P6: =IF($N6="","",Assumptions!$B$6*MAX(0.05,($N6/Assumptions!$B$11)^Assumptions!$B$12)) -> 0.0138 | Q6: =IF($P6="","",1-(1-$P6)^Assumptions!$B$7) -> 0.0671217 | R6: =IF($M6="","",$M6*Assumptions!$B$7) -> 55 | S6: =IF(OR($J6="",$Q6="",$Q6=0),"",($J6+$R6)/($Q6*(1-Assumptions!$B$4))) | T6: =IF(OR($K6="",$S6="",$S6=0),"",$K6/$S6) | U6: =IF(OR($K6="",$Q6=""),"",MAX(0,($K6-MAX($K6*Assumptions!$B$4,Assumptions!$B$5))*$Q6-$R6)) | V6: =IF($A6="","",IF($O6="FAIL","REJECT",IF($J6="","NEEDS PRICE",IF(OR($K6="",$L6=""),"NEEDS VALUATION",IF($T6>=Assumptions!$B$13,"BUY",IF($T6>=1,"MARGINAL","PASS")))))) -> NEEDS PRICE | W6: Taken | X6: [T1] Category-defining term. Aftermarket only.
A7: equipmentfinancing.com | B7: =IF($A7="","",IF(ISERROR(FIND(".",$A7)),"",LOWER(MID($A7,FIND(CHAR(1),SUBSTITUTE($A7,".",CHAR(1),LEN($A7)-LEN(SUBSTITUTE($A7,".",""))))+1,LEN($A7))))) -> com | C7: =IF($B7="","",IFERROR(INDEX(Rubric!$B$14:$B$23,MATCH($B7,Rubric!$A$14:$A$23,0)),INDEX(Rubric!$B$14:$B$23,MATCH("other",Rubric!$A$14:$A$23,0)))) -> 5 | D7: 5 | E7: 3 | F7: 3 | G7: 5 | H7: N | I7: N | M7: =IF($B7="","",IFERROR(INDEX(Rubric!$C$14:$C$23,MATCH($B7,Rubric!$A$14:$A$23,0)),INDEX(Rubric!$C$14:$C$23,MATCH("other",Rubric!$A$14:$A$23,0)))) -> 11 | N7: =IF(OR($A7="",$C7=""),"",$C7*Rubric!$B$5+$D7*Rubric!$B$6+$E7*Rubric!$B$7+$F7*Rubric!$B$8+$G7*Rubric!$B$9) -> 4.24 | O7: =IF($A7="","",IF(OR(UPPER($H7)="Y",UPPER($I7)="Y"),"FAIL","PASS")) -> PASS | P7: =IF($N7="","",Assumptions!$B$6*MAX(0.05,($N7/Assumptions!$B$11)^Assumptions!$B$12)) -> 0.014133333 | Q7: =IF($P7="","",1-(1-$P7)^Assumptions!$B$7) -> 0.068697188 | R7: =IF($M7="","",$M7*Assumptions!$B$7) -> 55 | S7: =IF(OR($J7="",$Q7="",$Q7=0),"",($J7+$R7)/($Q7*(1-Assumptions!$B$4))) | T7: =IF(OR($K7="",$S7="",$S7=0),"",$K7/$S7) | U7: =IF(OR($K7="",$Q7=""),"",MAX(0,($K7-MAX($K7*Assumptions!$B$4,Assumptions!$B$5))*$Q7-$R7)) | V7: =IF($A7="","",IF($O7="FAIL","REJECT",IF($J7="","NEEDS PRICE",IF(OR($K7="",$L7=""),"NEEDS VALUATION",IF($T7>=Assumptions!$B$13,"BUY",IF($T7>=1,"MARGINAL","PASS")))))) -> NEEDS PRICE | W7: Taken | X7: [T1] The exact-match phrase for the niche. Aftermarket only.
A8: equipmentleasing.com | B8: =IF($A8="","",IF(ISERROR(FIND(".",$A8)),"",LOWER(MID($A8,FIND(CHAR(1),SUBSTITUTE($A8,".",CHAR(1),LEN($A8)-LEN(SUBSTITUTE($A8,".",""))))+1,LEN($A8))))) -> com | C8: =IF($B8="","",IFERROR(INDEX(Rubric!$B$14:$B$23,MATCH($B8,Rubric!$A$14:$A$23,0)),INDEX(Rubric!$B$14:$B$23,MATCH("other",Rubric!$A$14:$A$23,0)))) -> 5 | D8: 5 | E8: 3 | F8: 3 | G8: 5 | H8: N | I8: N | M8: =IF($B8="","",IFERROR(INDEX(Rubric!$C$14:$C$23,MATCH($B8,Rubric!$A$14:$A$23,0)),INDEX(Rubric!$C$14:$C$23,MATCH("other",Rubric!$A$14:$A$23,0)))) -> 11 | N8: =IF(OR($A8="",$C8=""),"",$C8*Rubric!$B$5+$D8*Rubric!$B$6+$E8*Rubric!$B$7+$F8*Rubric!$B$8+$G8*Rubric!$B$9) -> 4.24 | O8: =IF($A8="","",IF(OR(UPPER($H8)="Y",UPPER($I8)="Y"),"FAIL","PASS")) -> PASS | P8: =IF($N8="","",Assumptions!$B$6*MAX(0.05,($N8/Assumptions!$B$11)^Assumptions!$B$12)) -> 0.014133333 | Q8: =IF($P8="","",1-(1-$P8)^Assumptions!$B$7) -> 0.068697188 | R8: =IF($M8="","",$M8*Assumptions!$B$7) -> 55 | S8: =IF(OR($J8="",$Q8="",$Q8=0),"",($J8+$R8)/($Q8*(1-Assumptions!$B$4))) | T8: =IF(OR($K8="",$S8="",$S8=0),"",$K8/$S8) | U8: =IF(OR($K8="",$Q8=""),"",MAX(0,($K8-MAX($K8*Assumptions!$B$4,Assumptions!$B$5))*$Q8-$R8)) | V8: =IF($A8="","",IF($O8="FAIL","REJECT",IF($J8="","NEEDS PRICE",IF(OR($K8="",$L8=""),"NEEDS VALUATION",IF($T8>=Assumptions!$B$13,"BUY",IF($T8>=1,"MARGINAL","PASS")))))) -> NEEDS PRICE | W8: Taken | X8: [T1] ELFA's own vocabulary. Aftermarket only.
A9: invoicefactoring.com | B9: =IF($A9="","",IF(ISERROR(FIND(".",$A9)),"",LOWER(MID($A9,FIND(CHAR(1),SUBSTITUTE($A9,".",CHAR(1),LEN($A9)-LEN(SUBSTITUTE($A9,".",""))))+1,LEN($A9))))) -> com | C9: =IF($B9="","",IFERROR(INDEX(Rubric!$B$14:$B$23,MATCH($B9,Rubric!$A$14:$A$23,0)),INDEX(Rubric!$B$14:$B$23,MATCH("other",Rubric!$A$14:$A$23,0)))) -> 5 | D9: 5 | E9: 3 | F9: 3 | G9: 5 | H9: N | I9: N | M9: =IF($B9="","",IFERROR(INDEX(Rubric!$C$14:$C$23,MATCH($B9,Rubric!$A$14:$A$23,0)),INDEX(Rubric!$C$14:$C$23,MATCH("other",Rubric!$A$14:$A$23,0)))) -> 11 | N9: =IF(OR($A9="",$C9=""),"",$C9*Rubric!$B$5+$D9*Rubric!$B$6+$E9*Rubric!$B$7+$F9*Rubric!$B$8+$G9*Rubric!$B$9) -> 4.24 | O9: =IF($A9="","",IF(OR(UPPER($H9)="Y",UPPER($I9)="Y"),"FAIL","PASS")) -> PASS | P9: =IF($N9="","",Assumptions!$B$6*MAX(0.05,($N9/Assumptions!$B$11)^Assumptions!$B$12)) -> 0.014133333 | Q9: =IF($P9="","",1-(1-$P9)^Assumptions!$B$7) -> 0.068697188 | R9: =IF($M9="","",$M9*Assumptions!$B$7) -> 55 | S9: =IF(OR($J9="",$Q9="",$Q9=0),"",($J9+$R9)/($Q9*(1-Assumptions!$B$4))) | T9: =IF(OR($K9="",$S9="",$S9=0),"",$K9/$S9) | U9: =IF(OR($K9="",$Q9=""),"",MAX(0,($K9-MAX($K9*Assumptions!$B$4,Assumptions!$B$5))*$Q9-$R9)) | V9: =IF($A9="","",IF($O9="FAIL","REJECT",IF($J9="","NEEDS PRICE",IF(OR($K9="",$L9=""),"NEEDS VALUATION",IF($T9>=Assumptions!$B$13,"BUY",IF($T9>=1,"MARGINAL","PASS")))))) -> NEEDS PRICE | W9: Taken | X9: [T1] High-CPC lending vertical. Aftermarket only.
A10: merchantcashadvance.com | B10: =IF($A10="","",IF(ISERROR(FIND(".",$A10)),"",LOWER(MID($A10,FIND(CHAR(1),SUBSTITUTE($A10,".",CHAR(1),LEN($A10)-LEN(SUBSTITUTE($A10,".",""))))+1,LEN($A10))))) -> com | C10: =IF($B10="","",IFERROR(INDEX(Rubric!$B$14:$B$23,MATCH($B10,Rubric!$A$14:$A$23,0)),INDEX(Rubric!$B$14:$B$23,MATCH("other",Rubric!$A$14:$A$23,0)))) -> 5 | D10: 5 | E10: 3 | F10: 2 | G10: 4 | H10: N | I10: N | M10: =IF($B10="","",IFERROR(INDEX(Rubric!$C$14:$C$23,MATCH($B10,Rubric!$A$14:$A$23,0)),INDEX(Rubric!$C$14:$C$23,MATCH("other",Rubric!$A$14:$A$23,0)))) -> 11 | N10: =IF(OR($A10="",$C10=""),"",$C10*Rubric!$B$5+$D10*Rubric!$B$6+$E10*Rubric!$B$7+$F10*Rubric!$B$8+$G10*Rubric!$B$9) -> 3.98 | O10: =IF($A10="","",IF(OR(UPPER($H10)="Y",UPPER($I10)="Y"),"FAIL","PASS")) -> PASS | P10: =IF($N10="","",Assumptions!$B$6*MAX(0.05,($N10/Assumptions!$B$11)^Assumptions!$B$12)) -> 0.013266667 | Q10: =IF($P10="","",1-(1-$P10)^Assumptions!$B$7) -> 0.064596484 | R10: =IF($M10="","",$M10*Assumptions!$B$7) -> 55 | S10: =IF(OR($J10="",$Q10="",$Q10=0),"",($J10+$R10)/($Q10*(1-Assumptions!$B$4))) | T10: =IF(OR($K10="",$S10="",$S10=0),"",$K10/$S10) | U10: =IF(OR($K10="",$Q10=""),"",MAX(0,($K10-MAX($K10*Assumptions!$B$4,Assumptions!$B$5))*$Q10-$R10)) | V10: =IF($A10="","",IF($O10="FAIL","REJECT",IF($J10="","NEEDS PRICE",IF(OR($K10="",$L10=""),"NEEDS VALUATION",IF($T10>=Assumptions!$B$13,"BUY",IF($T10>=1,"MARGINAL","PASS")))))) -> NEEDS PRICE | W10: Taken | X10: [T1] Very high CPC, long string. Aftermarket only.
A11: assetbasedlending.com | B11: =IF($A11="","",IF(ISERROR(FIND(".",$A11)),"",LOWER(MID($A11,FIND(CHAR(1),SUBSTITUTE($A11,".",CHAR(1),LEN($A11)-LEN(SUBSTITUTE($A11,".",""))))+1,LEN($A11))))) -> com | C11: =IF($B11="","",IFERROR(INDEX(Rubric!$B$14:$B$23,MATCH($B11,Rubric!$A$14:$A$23,0)),INDEX(Rubric!$B$14:$B$23,MATCH("other",Rubric!$A$14:$A$23,0)))) -> 5 | D11: 5 | E11: 3 | F11: 2 | G11: 4 | H11: N | I11: N | M11: =IF($B11="","",IFERROR(INDEX(Rubric!$C$14:$C$23,MATCH($B11,Rubric!$A$14:$A$23,0)),INDEX(Rubric!$C$14:$C$23,MATCH("other",Rubric!$A$14:$A$23,0)))) -> 11 | N11: =IF(OR($A11="",$C11=""),"",$C11*Rubric!$B$5+$D11*Rubric!$B$6+$E11*Rubric!$B$7+$F11*Rubric!$B$8+$G11*Rubric!$B$9) -> 3.98 | O11: =IF($A11="","",IF(OR(UPPER($H11)="Y",UPPER($I11)="Y"),"FAIL","PASS")) -> PASS | P11: =IF($N11="","",Assumptions!$B$6*MAX(0.05,($N11/Assumptions!$B$11)^Assumptions!$B$12)) -> 0.013266667 | Q11: =IF($P11="","",1-(1-$P11)^Assumptions!$B$7) -> 0.064596484 | R11: =IF($M11="","",$M11*Assumptions!$B$7) -> 55 | S11: =IF(OR($J11="",$Q11="",$Q11=0),"",($J11+$R11)/($Q11*(1-Assumptions!$B$4))) | T11: =IF(OR($K11="",$S11="",$S11=0),"",$K11/$S11) | U11: =IF(OR($K11="",$Q11=""),"",MAX(0,($K11-MAX($K11*Assumptions!$B$4,Assumptions!$B$5))*$Q11-$R11)) | V11: =IF($A11="","",IF($O11="FAIL","REJECT",IF($J11="","NEEDS PRICE",IF(OR($K11="",$L11=""),"NEEDS VALUATION",IF($T11>=Assumptions!$B$13,"BUY",IF($T11>=1,"MARGINAL","PASS")))))) -> NEEDS PRICE | W11: Taken | X11: [T1] ABL is a real institutional category. Aftermarket only.
A12: saleleaseback.com | B12: =IF($A12="","",IF(ISERROR(FIND(".",$A12)),"",LOWER(MID($A12,FIND(CHAR(1),SUBSTITUTE($A12,".",CHAR(1),LEN($A12)-LEN(SUBSTITUTE($A12,".",""))))+1,LEN($A12))))) -> com | C12: =IF($B12="","",IFERROR(INDEX(Rubric!$B$14:$B$23,MATCH($B12,Rubric!$A$14:$A$23,0)),INDEX(Rubric!$B$14:$B$23,MATCH("other",Rubric!$A$14:$A$23,0)))) -> 5 | D12: 4 | E12: 2 | F12: 3 | G12: 4 | H12: N | I12: N | M12: =IF($B12="","",IFERROR(INDEX(Rubric!$C$14:$C$23,MATCH($B12,Rubric!$A$14:$A$23,0)),INDEX(Rubric!$C$14:$C$23,MATCH("other",Rubric!$A$14:$A$23,0)))) -> 11 | N12: =IF(OR($A12="",$C12=""),"",$C12*Rubric!$B$5+$D12*Rubric!$B$6+$E12*Rubric!$B$7+$F12*Rubric!$B$8+$G12*Rubric!$B$9) -> 3.62 | O12: =IF($A12="","",IF(OR(UPPER($H12)="Y",UPPER($I12)="Y"),"FAIL","PASS")) -> PASS | P12: =IF($N12="","",Assumptions!$B$6*MAX(0.05,($N12/Assumptions!$B$11)^Assumptions!$B$12)) -> 0.012066667 | Q12: =IF($P12="","",1-(1-$P12)^Assumptions!$B$7) -> 0.058894753 | R12: =IF($M12="","",$M12*Assumptions!$B$7) -> 55 | S12: =IF(OR($J12="",$Q12="",$Q12=0),"",($J12+$R12)/($Q12*(1-Assumptions!$B$4))) | T12: =IF(OR($K12="",$S12="",$S12=0),"",$K12/$S12) | U12: =IF(OR($K12="",$Q12=""),"",MAX(0,($K12-MAX($K12*Assumptions!$B$4,Assumptions!$B$5))*$Q12-$R12)) | V12: =IF($A12="","",IF($O12="FAIL","REJECT",IF($J12="","NEEDS PRICE",IF(OR($K12="",$L12=""),"NEEDS VALUATION",IF($T12>=Assumptions!$B$13,"BUY",IF($T12>=1,"MARGINAL","PASS")))))) -> NEEDS PRICE | W12: Taken | X12: [T1] Structure term; narrower buyer pool than it looks.
A13: vendorfinancing.com | B13: =IF($A13="","",IF(ISERROR(FIND(".",$A13)),"",LOWER(MID($A13,FIND(CHAR(1),SUBSTITUTE($A13,".",CHAR(1),LEN($A13)-LEN(SUBSTITUTE($A13,".",""))))+1,LEN($A13))))) -> com | C13: =IF($B13="","",IFERROR(INDEX(Rubric!$B$14:$B$23,MATCH($B13,Rubric!$A$14:$A$23,0)),INDEX(Rubric!$B$14:$B$23,MATCH("other",Rubric!$A$14:$A$23,0)))) -> 5 | D13: 4 | E13: 2 | F13: 3 | G13: 5 | H13: N | I13: N | M13: =IF($B13="","",IFERROR(INDEX(Rubric!$C$14:$C$23,MATCH($B13,Rubric!$A$14:$A$23,0)),INDEX(Rubric!$C$14:$C$23,MATCH("other",Rubric!$A$14:$A$23,0)))) -> 11 | N13: =IF(OR($A13="",$C13=""),"",$C13*Rubric!$B$5+$D13*Rubric!$B$6+$E13*Rubric!$B$7+$F13*Rubric!$B$8+$G13*Rubric!$B$9) -> 3.72 | O13: =IF($A13="","",IF(OR(UPPER($H13)="Y",UPPER($I13)="Y"),"FAIL","PASS")) -> PASS | P13: =IF($N13="","",Assumptions!$B$6*MAX(0.05,($N13/Assumptions!$B$11)^Assumptions!$B$12)) -> 0.0124 | Q13: =IF($P13="","",1-(1-$P13)^Assumptions!$B$7) -> 0.060481348 | R13: =IF($M13="","",$M13*Assumptions!$B$7) -> 55 | S13: =IF(OR($J13="",$Q13="",$Q13=0),"",($J13+$R13)/($Q13*(1-Assumptions!$B$4))) | T13: =IF(OR($K13="",$S13="",$S13=0),"",$K13/$S13) | U13: =IF(OR($K13="",$Q13=""),"",MAX(0,($K13-MAX($K13*Assumptions!$B$4,Assumptions!$B$5))*$Q13-$R13)) | V13: =IF($A13="","",IF($O13="FAIL","REJECT",IF($J13="","NEEDS PRICE",IF(OR($K13="",$L13=""),"NEEDS VALUATION",IF($T13>=Assumptions!$B$13,"BUY",IF($T13>=1,"MARGINAL","PASS")))))) -> NEEDS PRICE | W13: Taken | X13: [T1] Vendor programs are a major equipment-finance channel.
A14: equipmentloans.com | B14: =IF($A14="","",IF(ISERROR(FIND(".",$A14)),"",LOWER(MID($A14,FIND(CHAR(1),SUBSTITUTE($A14,".",CHAR(1),LEN($A14)-LEN(SUBSTITUTE($A14,".",""))))+1,LEN($A14))))) -> com | C14: =IF($B14="","",IFERROR(INDEX(Rubric!$B$14:$B$23,MATCH($B14,Rubric!$A$14:$A$23,0)),INDEX(Rubric!$B$14:$B$23,MATCH("other",Rubric!$A$14:$A$23,0)))) -> 5 | D14: 5 | E14: 3 | F14: 4 | G14: 5 | H14: N | I14: N | M14: =IF($B14="","",IFERROR(INDEX(Rubric!$C$14:$C$23,MATCH($B14,Rubric!$A$14:$A$23,0)),INDEX(Rubric!$C$14:$C$23,MATCH("other",Rubric!$A$14:$A$23,0)))) -> 11 | N14: =IF(OR($A14="",$C14=""),"",$C14*Rubric!$B$5+$D14*Rubric!$B$6+$E14*Rubric!$B$7+$F14*Rubric!$B$8+$G14*Rubric!$B$9) -> 4.4 | O14: =IF($A14="","",IF(OR(UPPER($H14)="Y",UPPER($I14)="Y"),"FAIL","PASS")) -> PASS | P14: =IF($N14="","",Assumptions!$B$6*MAX(0.05,($N14/Assumptions!$B$11)^Assumptions!$B$12)) -> 0.014666667 | Q14: =IF($P14="","",1-(1-$P14)^Assumptions!$B$7) -> 0.071213541 | R14: =IF($M14="","",$M14*Assumptions!$B$7) -> 55 | S14: =IF(OR($J14="",$Q14="",$Q14=0),"",($J14+$R14)/($Q14*(1-Assumptions!$B$4))) | T14: =IF(OR($K14="",$S14="",$S14=0),"",$K14/$S14) | U14: =IF(OR($K14="",$Q14=""),"",MAX(0,($K14-MAX($K14*Assumptions!$B$4,Assumptions!$B$5))*$Q14-$R14)) | V14: =IF($A14="","",IF($O14="FAIL","REJECT",IF($J14="","NEEDS PRICE",IF(OR($K14="",$L14=""),"NEEDS VALUATION",IF($T14>=Assumptions!$B$13,"BUY",IF($T14>=1,"MARGINAL","PASS")))))) -> NEEDS PRICE | W14: Taken | X14: [T1] Shorter and cleaner than 'financing'. Aftermarket only.
A15: machineryfinancing.com | B15: =IF($A15="","",IF(ISERROR(FIND(".",$A15)),"",LOWER(MID($A15,FIND(CHAR(1),SUBSTITUTE($A15,".",CHAR(1),LEN($A15)-LEN(SUBSTITUTE($A15,".",""))))+1,LEN($A15))))) -> com | C15: =IF($B15="","",IFERROR(INDEX(Rubric!$B$14:$B$23,MATCH($B15,Rubric!$A$14:$A$23,0)),INDEX(Rubric!$B$14:$B$23,MATCH("other",Rubric!$A$14:$A$23,0)))) -> 5 | D15: 4 | E15: 3 | F15: 3 | G15: 4 | H15: N | I15: N | M15: =IF($B15="","",IFERROR(INDEX(Rubric!$C$14:$C$23,MATCH($B15,Rubric!$A$14:$A$23,0)),INDEX(Rubric!$C$14:$C$23,MATCH("other",Rubric!$A$14:$A$23,0)))) -> 11 | N15: =IF(OR($A15="",$C15=""),"",$C15*Rubric!$B$5+$D15*Rubric!$B$6+$E15*Rubric!$B$7+$F15*Rubric!$B$8+$G15*Rubric!$B$9) -> 3.84 | O15: =IF($A15="","",IF(OR(UPPER($H15)="Y",UPPER($I15)="Y"),"FAIL","PASS")) -> PASS | P15: =IF($N15="","",Assumptions!$B$6*MAX(0.05,($N15/Assumptions!$B$11)^Assumptions!$B$12)) -> 0.0128 | Q15: =IF($P15="","",1-(1-$P15)^Assumptions!$B$7) -> 0.062382438 | R15: =IF($M15="","",$M15*Assumptions!$B$7) -> 55 | S15: =IF(OR($J15="",$Q15="",$Q15=0),"",($J15+$R15)/($Q15*(1-Assumptions!$B$4))) | T15: =IF(OR($K15="",$S15="",$S15=0),"",$K15/$S15) | U15: =IF(OR($K15="",$Q15=""),"",MAX(0,($K15-MAX($K15*Assumptions!$B$4,Assumptions!$B$5))*$Q15-$R15)) | V15: =IF($A15="","",IF($O15="FAIL","REJECT",IF($J15="","NEEDS PRICE",IF(OR($K15="",$L15=""),"NEEDS VALUATION",IF($T15>=Assumptions!$B$13,"BUY",IF($T15>=1,"MARGINAL","PASS")))))) -> NEEDS PRICE | W15: Taken | X15: [T2] Machine tools / CNC buyers. Check availability.
A16: forkliftfinancing.com | B16: =IF($A16="","",IF(ISERROR(FIND(".",$A16)),"",LOWER(MID($A16,FIND(CHAR(1),SUBSTITUTE($A16,".",CHAR(1),LEN($A16)-LEN(SUBSTITUTE($A16,".",""))))+1,LEN($A16))))) -> com | C16: =IF($B16="","",IFERROR(INDEX(Rubric!$B$14:$B$23,MATCH($B16,Rubric!$A$14:$A$23,0)),INDEX(Rubric!$B$14:$B$23,MATCH("other",Rubric!$A$14:$A$23,0)))) -> 5 | D16: 4 | E16: 3 | F16: 3 | G16: 5 | H16: N | I16: N | M16: =IF($B16="","",IFERROR(INDEX(Rubric!$C$14:$C$23,MATCH($B16,Rubric!$A$14:$A$23,0)),INDEX(Rubric!$C$14:$C$23,MATCH("other",Rubric!$A$14:$A$23,0)))) -> 11 | N16: =IF(OR($A16="",$C16=""),"",$C16*Rubric!$B$5+$D16*Rubric!$B$6+$E16*Rubric!$B$7+$F16*Rubric!$B$8+$G16*Rubric!$B$9) -> 3.94 | O16: =IF($A16="","",IF(OR(UPPER($H16)="Y",UPPER($I16)="Y"),"FAIL","PASS")) -> PASS | P16: =IF($N16="","",Assumptions!$B$6*MAX(0.05,($N16/Assumptions!$B$11)^Assumptions!$B$12)) -> 0.013133333 | Q16: =IF($P16="","",1-(1-$P16)^Assumptions!$B$7) -> 0.063964327 | R16: =IF($M16="","",$M16*Assumptions!$B$7) -> 55 | S16: =IF(OR($J16="",$Q16="",$Q16=0),"",($J16+$R16)/($Q16*(1-Assumptions!$B$4))) | T16: =IF(OR($K16="",$S16="",$S16=0),"",$K16/$S16) | U16: =IF(OR($K16="",$Q16=""),"",MAX(0,($K16-MAX($K16*Assumptions!$B$4,Assumptions!$B$5))*$Q16-$R16)) | V16: =IF($A16="","",IF($O16="FAIL","REJECT",IF($J16="","NEEDS PRICE",IF(OR($K16="",$L16=""),"NEEDS VALUATION",IF($T16>=Assumptions!$B$13,"BUY",IF($T16>=1,"MARGINAL","PASS")))))) -> NEEDS PRICE | W16: Taken | X16: [T2] Material handling is a large, financeable category.
A17: fleetfinancing.com | B17: =IF($A17="","",IF(ISERROR(FIND(".",$A17)),"",LOWER(MID($A17,FIND(CHAR(1),SUBSTITUTE($A17,".",CHAR(1),LEN($A17)-LEN(SUBSTITUTE($A17,".",""))))+1,LEN($A17))))) -> com | C17: =IF($B17="","",IFERROR(INDEX(Rubric!$B$14:$B$23,MATCH($B17,Rubric!$A$14:$A$23,0)),INDEX(Rubric!$B$14:$B$23,MATCH("other",Rubric!$A$14:$A$23,0)))) -> 5 | D17: 5 | E17: 3 | F17: 4 | G17: 5 | H17: N | I17: N | M17: =IF($B17="","",IFERROR(INDEX(Rubric!$C$14:$C$23,MATCH($B17,Rubric!$A$14:$A$23,0)),INDEX(Rubric!$C$14:$C$23,MATCH("other",Rubric!$A$14:$A$23,0)))) -> 11 | N17: =IF(OR($A17="",$C17=""),"",$C17*Rubric!$B$5+$D17*Rubric!$B$6+$E17*Rubric!$B$7+$F17*Rubric!$B$8+$G17*Rubric!$B$9) -> 4.4 | O17: =IF($A17="","",IF(OR(UPPER($H17)="Y",UPPER($I17)="Y"),"FAIL","PASS")) -> PASS | P17: =IF($N17="","",Assumptions!$B$6*MAX(0.05,($N17/Assumptions!$B$11)^Assumptions!$B$12)) -> 0.014666667 | Q17: =IF($P17="","",1-(1-$P17)^Assumptions!$B$7) -> 0.071213541 | R17: =IF($M17="","",$M17*Assumptions!$B$7) -> 55 | S17: =IF(OR($J17="",$Q17="",$Q17=0),"",($J17+$R17)/($Q17*(1-Assumptions!$B$4))) | T17: =IF(OR($K17="",$S17="",$S17=0),"",$K17/$S17) | U17: =IF(OR($K17="",$Q17=""),"",MAX(0,($K17-MAX($K17*Assumptions!$B$4,Assumptions!$B$5))*$Q17-$R17)) | V17: =IF($A17="","",IF($O17="FAIL","REJECT",IF($J17="","NEEDS PRICE",IF(OR($K17="",$L17=""),"NEEDS VALUATION",IF($T17>=Assumptions!$B$13,"BUY",IF($T17>=1,"MARGINAL","PASS")))))) -> NEEDS PRICE | W17: Taken | X17: [T2] Fleet is high-ticket and repeat-purchase.
A18: cranefinancing.com | B18: =IF($A18="","",IF(ISERROR(FIND(".",$A18)),"",LOWER(MID($A18,FIND(CHAR(1),SUBSTITUTE($A18,".",CHAR(1),LEN($A18)-LEN(SUBSTITUTE($A18,".",""))))+1,LEN($A18))))) -> com | C18: =IF($B18="","",IFERROR(INDEX(Rubric!$B$14:$B$23,MATCH($B18,Rubric!$A$14:$A$23,0)),INDEX(Rubric!$B$14:$B$23,MATCH("other",Rubric!$A$14:$A$23,0)))) -> 5 | D18: 4 | E18: 2 | F18: 4 | G18: 5 | H18: N | I18: N | J18: 5000 | M18: =IF($B18="","",IFERROR(INDEX(Rubric!$C$14:$C$23,MATCH($B18,Rubric!$A$14:$A$23,0)),INDEX(Rubric!$C$14:$C$23,MATCH("other",Rubric!$A$14:$A$23,0)))) -> 11 | N18: =IF(OR($A18="",$C18=""),"",$C18*Rubric!$B$5+$D18*Rubric!$B$6+$E18*Rubric!$B$7+$F18*Rubric!$B$8+$G18*Rubric!$B$9) -> 3.88 | O18: =IF($A18="","",IF(OR(UPPER($H18)="Y",UPPER($I18)="Y"),"FAIL","PASS")) -> PASS | P18: =IF($N18="","",Assumptions!$B$6*MAX(0.05,($N18/Assumptions!$B$11)^Assumptions!$B$12)) -> 0.012933333 | Q18: =IF($P18="","",1-(1-$P18)^Assumptions!$B$7) -> 0.06301545 | R18: =IF($M18="","",$M18*Assumptions!$B$7) -> 55 | S18: =IF(OR($J18="",$Q18="",$Q18=0),"",($J18+$R18)/($Q18*(1-Assumptions!$B$4))) -> 100273.03 | T18: =IF(OR($K18="",$S18="",$S18=0),"",$K18/$S18) | U18: =IF(OR($K18="",$Q18=""),"",MAX(0,($K18-MAX($K18*Assumptions!$B$4,Assumptions!$B$5))*$Q18-$R18)) | V18: =IF($A18="","",IF($O18="FAIL","REJECT",IF($J18="","NEEDS PRICE",IF(OR($K18="",$L18=""),"NEEDS VALUATION",IF($T18>=Assumptions!$B$13,"BUY",IF($T18>=1,"MARGINAL","PASS")))))) -> NEEDS VALUATION | W18: Available - premium | X18: [T2] Heavy construction niche, small but wealthy buyer pool.
A19: truckfinancing.com | B19: =IF($A19="","",IF(ISERROR(FIND(".",$A19)),"",LOWER(MID($A19,FIND(CHAR(1),SUBSTITUTE($A19,".",CHAR(1),LEN($A19)-LEN(SUBSTITUTE($A19,".",""))))+1,LEN($A19))))) -> com | C19: =IF($B19="","",IFERROR(INDEX(Rubric!$B$14:$B$23,MATCH($B19,Rubric!$A$14:$A$23,0)),INDEX(Rubric!$B$14:$B$23,MATCH("other",Rubric!$A$14:$A$23,0)))) -> 5 | D19: 5 | E19: 3 | F19: 4 | G19: 5 | H19: N | I19: N | J19: 375000 | M19: =IF($B19="","",IFERROR(INDEX(Rubric!$C$14:$C$23,MATCH($B19,Rubric!$A$14:$A$23,0)),INDEX(Rubric!$C$14:$C$23,MATCH("other",Rubric!$A$14:$A$23,0)))) -> 11 | N19: =IF(OR($A19="",$C19=""),"",$C19*Rubric!$B$5+$D19*Rubric!$B$6+$E19*Rubric!$B$7+$F19*Rubric!$B$8+$G19*Rubric!$B$9) -> 4.4 | O19: =IF($A19="","",IF(OR(UPPER($H19)="Y",UPPER($I19)="Y"),"FAIL","PASS")) -> PASS | P19: =IF($N19="","",Assumptions!$B$6*MAX(0.05,($N19/Assumptions!$B$11)^Assumptions!$B$12)) -> 0.014666667 | Q19: =IF($P19="","",1-(1-$P19)^Assumptions!$B$7) -> 0.071213541 | R19: =IF($M19="","",$M19*Assumptions!$B$7) -> 55 | S19: =IF(OR($J19="",$Q19="",$Q19=0),"",($J19+$R19)/($Q19*(1-Assumptions!$B$4))) -> 6583281 | T19: =IF(OR($K19="",$S19="",$S19=0),"",$K19/$S19) | U19: =IF(OR($K19="",$Q19=""),"",MAX(0,($K19-MAX($K19*Assumptions!$B$4,Assumptions!$B$5))*$Q19-$R19)) | V19: =IF($A19="","",IF($O19="FAIL","REJECT",IF($J19="","NEEDS PRICE",IF(OR($K19="",$L19=""),"NEEDS VALUATION",IF($T19>=Assumptions!$B$13,"BUY",IF($T19>=1,"MARGINAL","PASS")))))) -> NEEDS VALUATION | W19: Available - premium | X19: [T2] Trucking is the single biggest equipment-finance vertical.
A20: trailerfinancing.com | B20: =IF($A20="","",IF(ISERROR(FIND(".",$A20)),"",LOWER(MID($A20,FIND(CHAR(1),SUBSTITUTE($A20,".",CHAR(1),LEN($A20)-LEN(SUBSTITUTE($A20,".",""))))+1,LEN($A20))))) -> com | C20: =IF($B20="","",IFERROR(INDEX(Rubric!$B$14:$B$23,MATCH($B20,Rubric!$A$14:$A$23,0)),INDEX(Rubric!$B$14:$B$23,MATCH("other",Rubric!$A$14:$A$23,0)))) -> 5 | D20: 4 | E20: 2 | F20: 3 | G20: 5 | H20: N | I20: N | J20: 4888 | M20: =IF($B20="","",IFERROR(INDEX(Rubric!$C$14:$C$23,MATCH($B20,Rubric!$A$14:$A$23,0)),INDEX(Rubric!$C$14:$C$23,MATCH("other",Rubric!$A$14:$A$23,0)))) -> 11 | N20: =IF(OR($A20="",$C20=""),"",$C20*Rubric!$B$5+$D20*Rubric!$B$6+$E20*Rubric!$B$7+$F20*Rubric!$B$8+$G20*Rubric!$B$9) -> 3.72 | O20: =IF($A20="","",IF(OR(UPPER($H20)="Y",UPPER($I20)="Y"),"FAIL","PASS")) -> PASS | P20: =IF($N20="","",Assumptions!$B$6*MAX(0.05,($N20/Assumptions!$B$11)^Assumptions!$B$12)) -> 0.0124 | Q20: =IF($P20="","",1-(1-$P20)^Assumptions!$B$7) -> 0.060481348 | R20: =IF($M20="","",$M20*Assumptions!$B$7) -> 55 | S20: =IF(OR($J20="",$Q20="",$Q20=0),"",($J20+$R20)/($Q20*(1-Assumptions!$B$4))) -> 102159.59 | T20: =IF(OR($K20="",$S20="",$S20=0),"",$K20/$S20) | U20: =IF(OR($K20="",$Q20=""),"",MAX(0,($K20-MAX($K20*Assumptions!$B$4,Assumptions!$B$5))*$Q20-$R20)) | V20: =IF($A20="","",IF($O20="FAIL","REJECT",IF($J20="","NEEDS PRICE",IF(OR($K20="",$L20=""),"NEEDS VALUATION",IF($T20>=Assumptions!$B$13,"BUY",IF($T20>=1,"MARGINAL","PASS")))))) -> NEEDS VALUATION | W20: Available - premium | X20: [T2] Adjacent to trucking.
A21: dentalfinancing.com | B21: =IF($A21="","",IF(ISERROR(FIND(".",$A21)),"",LOWER(MID($A21,FIND(CHAR(1),SUBSTITUTE($A21,".",CHAR(1),LEN($A21)-LEN(SUBSTITUTE($A21,".",""))))+1,LEN($A21))))) -> com | C21: =IF($B21="","",IFERROR(INDEX(Rubric!$B$14:$B$23,MATCH($B21,Rubric!$A$14:$A$23,0)),INDEX(Rubric!$B$14:$B$23,MATCH("other",Rubric!$A$14:$A$23,0)))) -> 5 | D21: 4 | E21: 3 | F21: 3 | G21: 5 | H21: N | I21: N | M21: =IF($B21="","",IFERROR(INDEX(Rubric!$C$14:$C$23,MATCH($B21,Rubric!$A$14:$A$23,0)),INDEX(Rubric!$C$14:$C$23,MATCH("other",Rubric!$A$14:$A$23,0)))) -> 11 | N21: =IF(OR($A21="",$C21=""),"",$C21*Rubric!$B$5+$D21*Rubric!$B$6+$E21*Rubric!$B$7+$F21*Rubric!$B$8+$G21*Rubric!$B$9) -> 3.94 | O21: =IF($A21="","",IF(OR(UPPER($H21)="Y",UPPER($I21)="Y"),"FAIL","PASS")) -> PASS | P21: =IF($N21="","",Assumptions!$B$6*MAX(0.05,($N21/Assumptions!$B$11)^Assumptions!$B$12)) -> 0.013133333 | Q21: =IF($P21="","",1-(1-$P21)^Assumptions!$B$7) -> 0.063964327 | R21: =IF($M21="","",$M21*Assumptions!$B$7) -> 55 | S21: =IF(OR($J21="",$Q21="",$Q21=0),"",($J21+$R21)/($Q21*(1-Assumptions!$B$4))) | T21: =IF(OR($K21="",$S21="",$S21=0),"",$K21/$S21) | U21: =IF(OR($K21="",$Q21=""),"",MAX(0,($K21-MAX($K21*Assumptions!$B$4,Assumptions!$B$5))*$Q21-$R21)) | V21: =IF($A21="","",IF($O21="FAIL","REJECT",IF($J21="","NEEDS PRICE",IF(OR($K21="",$L21=""),"NEEDS VALUATION",IF($T21>=Assumptions!$B$13,"BUY",IF($T21>=1,"MARGINAL","PASS")))))) -> NEEDS PRICE | W21: Taken | X21: [T2] Dental practices finance chairs and imaging constantly.
A22: medicalleasing.com | B22: =IF($A22="","",IF(ISERROR(FIND(".",$A22)),"",LOWER(MID($A22,FIND(CHAR(1),SUBSTITUTE($A22,".",CHAR(1),LEN($A22)-LEN(SUBSTITUTE($A22,".",""))))+1,LEN($A22))))) -> com | C22: =IF($B22="","",IFERROR(INDEX(Rubric!$B$14:$B$23,MATCH($B22,Rubric!$A$14:$A$23,0)),INDEX(Rubric!$B$14:$B$23,MATCH("other",Rubric!$A$14:$A$23,0)))) -> 5 | D22: 4 | E22: 3 | F22: 4 | G22: 4 | H22: N | I22: N | M22: =IF($B22="","",IFERROR(INDEX(Rubric!$C$14:$C$23,MATCH($B22,Rubric!$A$14:$A$23,0)),INDEX(Rubric!$C$14:$C$23,MATCH("other",Rubric!$A$14:$A$23,0)))) -> 11 | N22: =IF(OR($A22="",$C22=""),"",$C22*Rubric!$B$5+$D22*Rubric!$B$6+$E22*Rubric!$B$7+$F22*Rubric!$B$8+$G22*Rubric!$B$9) -> 4 | O22: =IF($A22="","",IF(OR(UPPER($H22)="Y",UPPER($I22)="Y"),"FAIL","PASS")) -> PASS | P22: =IF($N22="","",Assumptions!$B$6*MAX(0.05,($N22/Assumptions!$B$11)^Assumptions!$B$12)) -> 0.013333333 | Q22: =IF($P22="","",1-(1-$P22)^Assumptions!$B$7) -> 0.064912435 | R22: =IF($M22="","",$M22*Assumptions!$B$7) -> 55 | S22: =IF(OR($J22="",$Q22="",$Q22=0),"",($J22+$R22)/($Q22*(1-Assumptions!$B$4))) | T22: =IF(OR($K22="",$S22="",$S22=0),"",$K22/$S22) | U22: =IF(OR($K22="",$Q22=""),"",MAX(0,($K22-MAX($K22*Assumptions!$B$4,Assumptions!$B$5))*$Q22-$R22)) | V22: =IF($A22="","",IF($O22="FAIL","REJECT",IF($J22="","NEEDS PRICE",IF(OR($K22="",$L22=""),"NEEDS VALUATION",IF($T22>=Assumptions!$B$13,"BUY",IF($T22>=1,"MARGINAL","PASS")))))) -> NEEDS PRICE | W22: Taken | X22: [T2] Imaging and diagnostic equipment leasing.
A23: solarfinancing.com | B23: =IF($A23="","",IF(ISERROR(FIND(".",$A23)),"",LOWER(MID($A23,FIND(CHAR(1),SUBSTITUTE($A23,".",CHAR(1),LEN($A23)-LEN(SUBSTITUTE($A23,".",""))))+1,LEN($A23))))) -> com | C23: =IF($B23="","",IFERROR(INDEX(Rubric!$B$14:$B$23,MATCH($B23,Rubric!$A$14:$A$23,0)),INDEX(Rubric!$B$14:$B$23,MATCH("other",Rubric!$A$14:$A$23,0)))) -> 5 | D23: 4 | E23: 3 | F23: 4 | G23: 5 | H23: N | I23: N | M23: =IF($B23="","",IFERROR(INDEX(Rubric!$C$14:$C$23,MATCH($B23,Rubric!$A$14:$A$23,0)),INDEX(Rubric!$C$14:$C$23,MATCH("other",Rubric!$A$14:$A$23,0)))) -> 11 | N23: =IF(OR($A23="",$C23=""),"",$C23*Rubric!$B$5+$D23*Rubric!$B$6+$E23*Rubric!$B$7+$F23*Rubric!$B$8+$G23*Rubric!$B$9) -> 4.1 | O23: =IF($A23="","",IF(OR(UPPER($H23)="Y",UPPER($I23)="Y"),"FAIL","PASS")) -> PASS | P23: =IF($N23="","",Assumptions!$B$6*MAX(0.05,($N23/Assumptions!$B$11)^Assumptions!$B$12)) -> 0.013666667 | Q23: =IF($P23="","",1-(1-$P23)^Assumptions!$B$7) -> 0.066490908 | R23: =IF($M23="","",$M23*Assumptions!$B$7) -> 55 | S23: =IF(OR($J23="",$Q23="",$Q23=0),"",($J23+$R23)/($Q23*(1-Assumptions!$B$4))) | T23: =IF(OR($K23="",$S23="",$S23=0),"",$K23/$S23) | U23: =IF(OR($K23="",$Q23=""),"",MAX(0,($K23-MAX($K23*Assumptions!$B$4,Assumptions!$B$5))*$Q23-$R23)) | V23: =IF($A23="","",IF($O23="FAIL","REJECT",IF($J23="","NEEDS PRICE",IF(OR($K23="",$L23=""),"NEEDS VALUATION",IF($T23>=Assumptions!$B$13,"BUY",IF($T23>=1,"MARGINAL","PASS")))))) -> NEEDS PRICE | W23: Taken | X23: [T2] Commercial solar is heavily financed.
A24: brewingfinancing.com | B24: =IF($A24="","",IF(ISERROR(FIND(".",$A24)),"",LOWER(MID($A24,FIND(CHAR(1),SUBSTITUTE($A24,".",CHAR(1),LEN($A24)-LEN(SUBSTITUTE($A24,".",""))))+1,LEN($A24))))) -> com | C24: =IF($B24="","",IFERROR(INDEX(Rubric!$B$14:$B$23,MATCH($B24,Rubric!$A$14:$A$23,0)),INDEX(Rubric!$B$14:$B$23,MATCH("other",Rubric!$A$14:$A$23,0)))) -> 5 | D24: 3 | E24: 2 | F24: 3 | G24: 4 | H24: N | I24: N | J24: 22.99 | K24: 285 | L24: HumbleWorth brokerage 2026-08-03 (mktpl $59, auction $0) | M24: =IF($B24="","",IFERROR(INDEX(Rubric!$C$14:$C$23,MATCH($B24,Rubric!$A$14:$A$23,0)),INDEX(Rubric!$C$14:$C$23,MATCH("other",Rubric!$A$14:$A$23,0)))) -> 11 | N24: =IF(OR($A24="",$C24=""),"",$C24*Rubric!$B$5+$D24*Rubric!$B$6+$E24*Rubric!$B$7+$F24*Rubric!$B$8+$G24*Rubric!$B$9) -> 3.32 | O24: =IF($A24="","",IF(OR(UPPER($H24)="Y",UPPER($I24)="Y"),"FAIL","PASS")) -> PASS | P24: =IF($N24="","",Assumptions!$B$6*MAX(0.05,($N24/Assumptions!$B$11)^Assumptions!$B$12)) -> 0.011066667 | Q24: =IF($P24="","",1-(1-$P24)^Assumptions!$B$7) -> 0.054122101 | R24: =IF($M24="","",$M24*Assumptions!$B$7) -> 55 | S24: =IF(OR($J24="",$Q24="",$Q24=0),"",($J24+$R24)/($Q24*(1-Assumptions!$B$4))) -> 1801.2512 | T24: =IF(OR($K24="",$S24="",$S24=0),"",$K24/$S24) -> 0.15822335 | U24: =IF(OR($K24="",$Q24=""),"",MAX(0,($K24-MAX($K24*Assumptions!$B$4,Assumptions!$B$5))*$Q24-$R24)) -> 0 | V24: =IF($A24="","",IF($O24="FAIL","REJECT",IF($J24="","NEEDS PRICE",IF(OR($K24="",$L24=""),"NEEDS VALUATION",IF($T24>=Assumptions!$B$13,"BUY",IF($T24>=1,"MARGINAL","PASS")))))) -> PASS | W24: Available - reg | X24: [T2] Narrow. Included as a deliberate low-scorer for contrast.
A25: kitchenfinancing.com | B25: =IF($A25="","",IF(ISERROR(FIND(".",$A25)),"",LOWER(MID($A25,FIND(CHAR(1),SUBSTITUTE($A25,".",CHAR(1),LEN($A25)-LEN(SUBSTITUTE($A25,".",""))))+1,LEN($A25))))) -> com | C25: =IF($B25="","",IFERROR(INDEX(Rubric!$B$14:$B$23,MATCH($B25,Rubric!$A$14:$A$23,0)),INDEX(Rubric!$B$14:$B$23,MATCH("other",Rubric!$A$14:$A$23,0)))) -> 5 | D25: 3 | E25: 2 | F25: 3 | G25: 4 | H25: N | I25: N | J25: 2788 | M25: =IF($B25="","",IFERROR(INDEX(Rubric!$C$14:$C$23,MATCH($B25,Rubric!$A$14:$A$23,0)),INDEX(Rubric!$C$14:$C$23,MATCH("other",Rubric!$A$14:$A$23,0)))) -> 11 | N25: =IF(OR($A25="",$C25=""),"",$C25*Rubric!$B$5+$D25*Rubric!$B$6+$E25*Rubric!$B$7+$F25*Rubric!$B$8+$G25*Rubric!$B$9) -> 3.32 | O25: =IF($A25="","",IF(OR(UPPER($H25)="Y",UPPER($I25)="Y"),"FAIL","PASS")) -> PASS | P25: =IF($N25="","",Assumptions!$B$6*MAX(0.05,($N25/Assumptions!$B$11)^Assumptions!$B$12)) -> 0.011066667 | Q25: =IF($P25="","",1-(1-$P25)^Assumptions!$B$7) -> 0.054122101 | R25: =IF($M25="","",$M25*Assumptions!$B$7) -> 55 | S25: =IF(OR($J25="",$Q25="",$Q25=0),"",($J25+$R25)/($Q25*(1-Assumptions!$B$4))) -> 65661.716 | T25: =IF(OR($K25="",$S25="",$S25=0),"",$K25/$S25) | U25: =IF(OR($K25="",$Q25=""),"",MAX(0,($K25-MAX($K25*Assumptions!$B$4,Assumptions!$B$5))*$Q25-$R25)) | V25: =IF($A25="","",IF($O25="FAIL","REJECT",IF($J25="","NEEDS PRICE",IF(OR($K25="",$L25=""),"NEEDS VALUATION",IF($T25>=Assumptions!$B$13,"BUY",IF($T25>=1,"MARGINAL","PASS")))))) -> NEEDS VALUATION | W25: Available - premium | X25: [T2] Restaurant build-outs. Ambiguous — reads residential.
A26: hvacfinancing.com | B26: =IF($A26="","",IF(ISERROR(FIND(".",$A26)),"",LOWER(MID($A26,FIND(CHAR(1),SUBSTITUTE($A26,".",CHAR(1),LEN($A26)-LEN(SUBSTITUTE($A26,".",""))))+1,LEN($A26))))) -> com | C26: =IF($B26="","",IFERROR(INDEX(Rubric!$B$14:$B$23,MATCH($B26,Rubric!$A$14:$A$23,0)),INDEX(Rubric!$B$14:$B$23,MATCH("other",Rubric!$A$14:$A$23,0)))) -> 5 | D26: 4 | E26: 3 | F26: 4 | G26: 4 | H26: N | I26: N | M26: =IF($B26="","",IFERROR(INDEX(Rubric!$C$14:$C$23,MATCH($B26,Rubric!$A$14:$A$23,0)),INDEX(Rubric!$C$14:$C$23,MATCH("other",Rubric!$A$14:$A$23,0)))) -> 11 | N26: =IF(OR($A26="",$C26=""),"",$C26*Rubric!$B$5+$D26*Rubric!$B$6+$E26*Rubric!$B$7+$F26*Rubric!$B$8+$G26*Rubric!$B$9) -> 4 | O26: =IF($A26="","",IF(OR(UPPER($H26)="Y",UPPER($I26)="Y"),"FAIL","PASS")) -> PASS | P26: =IF($N26="","",Assumptions!$B$6*MAX(0.05,($N26/Assumptions!$B$11)^Assumptions!$B$12)) -> 0.013333333 | Q26: =IF($P26="","",1-(1-$P26)^Assumptions!$B$7) -> 0.064912435 | R26: =IF($M26="","",$M26*Assumptions!$B$7) -> 55 | S26: =IF(OR($J26="",$Q26="",$Q26=0),"",($J26+$R26)/($Q26*(1-Assumptions!$B$4))) | T26: =IF(OR($K26="",$S26="",$S26=0),"",$K26/$S26) | U26: =IF(OR($K26="",$Q26=""),"",MAX(0,($K26-MAX($K26*Assumptions!$B$4,Assumptions!$B$5))*$Q26-$R26)) | V26: =IF($A26="","",IF($O26="FAIL","REJECT",IF($J26="","NEEDS PRICE",IF(OR($K26="",$L26=""),"NEEDS VALUATION",IF($T26>=Assumptions!$B$13,"BUY",IF($T26>=1,"MARGINAL","PASS")))))) -> NEEDS PRICE | W26: Taken | X26: [T2] Contractor equipment plus consumer-facing crossover.
A27: printfinancing.com | B27: =IF($A27="","",IF(ISERROR(FIND(".",$A27)),"",LOWER(MID($A27,FIND(CHAR(1),SUBSTITUTE($A27,".",CHAR(1),LEN($A27)-LEN(SUBSTITUTE($A27,".",""))))+1,LEN($A27))))) -> com | C27: =IF($B27="","",IFERROR(INDEX(Rubric!$B$14:$B$23,MATCH($B27,Rubric!$A$14:$A$23,0)),INDEX(Rubric!$B$14:$B$23,MATCH("other",Rubric!$A$14:$A$23,0)))) -> 5 | D27: 3 | E27: 2 | F27: 4 | G27: 4 | H27: N | I27: N | J27: 22.99 | M27: =IF($B27="","",IFERROR(INDEX(Rubric!$C$14:$C$23,MATCH($B27,Rubric!$A$14:$A$23,0)),INDEX(Rubric!$C$14:$C$23,MATCH("other",Rubric!$A$14:$A$23,0)))) -> 11 | N27: =IF(OR($A27="",$C27=""),"",$C27*Rubric!$B$5+$D27*Rubric!$B$6+$E27*Rubric!$B$7+$F27*Rubric!$B$8+$G27*Rubric!$B$9) -> 3.48 | O27: =IF($A27="","",IF(OR(UPPER($H27)="Y",UPPER($I27)="Y"),"FAIL","PASS")) -> PASS | P27: =IF($N27="","",Assumptions!$B$6*MAX(0.05,($N27/Assumptions!$B$11)^Assumptions!$B$12)) -> 0.0116 | Q27: =IF($P27="","",1-(1-$P27)^Assumptions!$B$7) -> 0.056669919 | R27: =IF($M27="","",$M27*Assumptions!$B$7) -> 55 | S27: =IF(OR($J27="",$Q27="",$Q27=0),"",($J27+$R27)/($Q27*(1-Assumptions!$B$4))) -> 1720.2689 | T27: =IF(OR($K27="",$S27="",$S27=0),"",$K27/$S27) | U27: =IF(OR($K27="",$Q27=""),"",MAX(0,($K27-MAX($K27*Assumptions!$B$4,Assumptions!$B$5))*$Q27-$R27)) | V27: =IF($A27="","",IF($O27="FAIL","REJECT",IF($J27="","NEEDS PRICE",IF(OR($K27="",$L27=""),"NEEDS VALUATION",IF($T27>=Assumptions!$B$13,"BUY",IF($T27>=1,"MARGINAL","PASS")))))) -> NEEDS VALUATION | W27: Available - reg | X27: [T2] Commercial printing is a shrinking sector.
A28: laundryfinancing.com | B28: =IF($A28="","",IF(ISERROR(FIND(".",$A28)),"",LOWER(MID($A28,FIND(CHAR(1),SUBSTITUTE($A28,".",CHAR(1),LEN($A28)-LEN(SUBSTITUTE($A28,".",""))))+1,LEN($A28))))) -> com | C28: =IF($B28="","",IFERROR(INDEX(Rubric!$B$14:$B$23,MATCH($B28,Rubric!$A$14:$A$23,0)),INDEX(Rubric!$B$14:$B$23,MATCH("other",Rubric!$A$14:$A$23,0)))) -> 5 | D28: 3 | E28: 2 | F28: 3 | G28: 4 | H28: N | I28: N | M28: =IF($B28="","",IFERROR(INDEX(Rubric!$C$14:$C$23,MATCH($B28,Rubric!$A$14:$A$23,0)),INDEX(Rubric!$C$14:$C$23,MATCH("other",Rubric!$A$14:$A$23,0)))) -> 11 | N28: =IF(OR($A28="",$C28=""),"",$C28*Rubric!$B$5+$D28*Rubric!$B$6+$E28*Rubric!$B$7+$F28*Rubric!$B$8+$G28*Rubric!$B$9) -> 3.32 | O28: =IF($A28="","",IF(OR(UPPER($H28)="Y",UPPER($I28)="Y"),"FAIL","PASS")) -> PASS | P28: =IF($N28="","",Assumptions!$B$6*MAX(0.05,($N28/Assumptions!$B$11)^Assumptions!$B$12)) -> 0.011066667 | Q28: =IF($P28="","",1-(1-$P28)^Assumptions!$B$7) -> 0.054122101 | R28: =IF($M28="","",$M28*Assumptions!$B$7) -> 55 | S28: =IF(OR($J28="",$Q28="",$Q28=0),"",($J28+$R28)/($Q28*(1-Assumptions!$B$4))) | T28: =IF(OR($K28="",$S28="",$S28=0),"",$K28/$S28) | U28: =IF(OR($K28="",$Q28=""),"",MAX(0,($K28-MAX($K28*Assumptions!$B$4,Assumptions!$B$5))*$Q28-$R28)) | V28: =IF($A28="","",IF($O28="FAIL","REJECT",IF($J28="","NEEDS PRICE",IF(OR($K28="",$L28=""),"NEEDS VALUATION",IF($T28>=Assumptions!$B$13,"BUY",IF($T28>=1,"MARGINAL","PASS")))))) -> NEEDS PRICE | W28: Taken | X28: [T2] Laundromat equipment is genuinely financed, small pool.
A29: gymfinancing.com | B29: =IF($A29="","",IF(ISERROR(FIND(".",$A29)),"",LOWER(MID($A29,FIND(CHAR(1),SUBSTITUTE($A29,".",CHAR(1),LEN($A29)-LEN(SUBSTITUTE($A29,".",""))))+1,LEN($A29))))) -> com | C29: =IF($B29="","",IFERROR(INDEX(Rubric!$B$14:$B$23,MATCH($B29,Rubric!$A$14:$A$23,0)),INDEX(Rubric!$B$14:$B$23,MATCH("other",Rubric!$A$14:$A$23,0)))) -> 5 | D29: 3 | E29: 2 | F29: 4 | G29: 4 | H29: N | I29: N | J29: 18800 | M29: =IF($B29="","",IFERROR(INDEX(Rubric!$C$14:$C$23,MATCH($B29,Rubric!$A$14:$A$23,0)),INDEX(Rubric!$C$14:$C$23,MATCH("other",Rubric!$A$14:$A$23,0)))) -> 11 | N29: =IF(OR($A29="",$C29=""),"",$C29*Rubric!$B$5+$D29*Rubric!$B$6+$E29*Rubric!$B$7+$F29*Rubric!$B$8+$G29*Rubric!$B$9) -> 3.48 | O29: =IF($A29="","",IF(OR(UPPER($H29)="Y",UPPER($I29)="Y"),"FAIL","PASS")) -> PASS | P29: =IF($N29="","",Assumptions!$B$6*MAX(0.05,($N29/Assumptions!$B$11)^Assumptions!$B$12)) -> 0.0116 | Q29: =IF($P29="","",1-(1-$P29)^Assumptions!$B$7) -> 0.056669919 | R29: =IF($M29="","",$M29*Assumptions!$B$7) -> 55 | S29: =IF(OR($J29="",$Q29="",$Q29=0),"",($J29+$R29)/($Q29*(1-Assumptions!$B$4))) -> 415895.25 | T29: =IF(OR($K29="",$S29="",$S29=0),"",$K29/$S29) | U29: =IF(OR($K29="",$Q29=""),"",MAX(0,($K29-MAX($K29*Assumptions!$B$4,Assumptions!$B$5))*$Q29-$R29)) | V29: =IF($A29="","",IF($O29="FAIL","REJECT",IF($J29="","NEEDS PRICE",IF(OR($K29="",$L29=""),"NEEDS VALUATION",IF($T29>=Assumptions!$B$13,"BUY",IF($T29>=1,"MARGINAL","PASS")))))) -> NEEDS VALUATION | W29: Available - premium | X29: [T2] Fitness equipment leasing.
A30: farmfinancing.com | B30: =IF($A30="","",IF(ISERROR(FIND(".",$A30)),"",LOWER(MID($A30,FIND(CHAR(1),SUBSTITUTE($A30,".",CHAR(1),LEN($A30)-LEN(SUBSTITUTE($A30,".",""))))+1,LEN($A30))))) -> com | C30: =IF($B30="","",IFERROR(INDEX(Rubric!$B$14:$B$23,MATCH($B30,Rubric!$A$14:$A$23,0)),INDEX(Rubric!$B$14:$B$23,MATCH("other",Rubric!$A$14:$A$23,0)))) -> 5 | D30: 4 | E30: 3 | F30: 4 | G30: 5 | H30: N | I30: N | M30: =IF($B30="","",IFERROR(INDEX(Rubric!$C$14:$C$23,MATCH($B30,Rubric!$A$14:$A$23,0)),INDEX(Rubric!$C$14:$C$23,MATCH("other",Rubric!$A$14:$A$23,0)))) -> 11 | N30: =IF(OR($A30="",$C30=""),"",$C30*Rubric!$B$5+$D30*Rubric!$B$6+$E30*Rubric!$B$7+$F30*Rubric!$B$8+$G30*Rubric!$B$9) -> 4.1 | O30: =IF($A30="","",IF(OR(UPPER($H30)="Y",UPPER($I30)="Y"),"FAIL","PASS")) -> PASS | P30: =IF($N30="","",Assumptions!$B$6*MAX(0.05,($N30/Assumptions!$B$11)^Assumptions!$B$12)) -> 0.013666667 | Q30: =IF($P30="","",1-(1-$P30)^Assumptions!$B$7) -> 0.066490908 | R30: =IF($M30="","",$M30*Assumptions!$B$7) -> 55 | S30: =IF(OR($J30="",$Q30="",$Q30=0),"",($J30+$R30)/($Q30*(1-Assumptions!$B$4))) | T30: =IF(OR($K30="",$S30="",$S30=0),"",$K30/$S30) | U30: =IF(OR($K30="",$Q30=""),"",MAX(0,($K30-MAX($K30*Assumptions!$B$4,Assumptions!$B$5))*$Q30-$R30)) | V30: =IF($A30="","",IF($O30="FAIL","REJECT",IF($J30="","NEEDS PRICE",IF(OR($K30="",$L30=""),"NEEDS VALUATION",IF($T30>=Assumptions!$B$13,"BUY",IF($T30>=1,"MARGINAL","PASS")))))) -> NEEDS PRICE | W30: Taken | X30: [T2] Ag equipment is a major financed category.
A31: agequipmentloans.com | B31: =IF($A31="","",IF(ISERROR(FIND(".",$A31)),"",LOWER(MID($A31,FIND(CHAR(1),SUBSTITUTE($A31,".",CHAR(1),LEN($A31)-LEN(SUBSTITUTE($A31,".",""))))+1,LEN($A31))))) -> com | C31: =IF($B31="","",IFERROR(INDEX(Rubric!$B$14:$B$23,MATCH($B31,Rubric!$A$14:$A$23,0)),INDEX(Rubric!$B$14:$B$23,MATCH("other",Rubric!$A$14:$A$23,0)))) -> 5 | D31: 3 | E31: 2 | F31: 3 | G31: 3 | H31: N | I31: N | J31: 22.99 | M31: =IF($B31="","",IFERROR(INDEX(Rubric!$C$14:$C$23,MATCH($B31,Rubric!$A$14:$A$23,0)),INDEX(Rubric!$C$14:$C$23,MATCH("other",Rubric!$A$14:$A$23,0)))) -> 11 | N31: =IF(OR($A31="",$C31=""),"",$C31*Rubric!$B$5+$D31*Rubric!$B$6+$E31*Rubric!$B$7+$F31*Rubric!$B$8+$G31*Rubric!$B$9) -> 3.22 | O31: =IF($A31="","",IF(OR(UPPER($H31)="Y",UPPER($I31)="Y"),"FAIL","PASS")) -> PASS | P31: =IF($N31="","",Assumptions!$B$6*MAX(0.05,($N31/Assumptions!$B$11)^Assumptions!$B$12)) -> 0.010733333 | Q31: =IF($P31="","",1-(1-$P31)^Assumptions!$B$7) -> 0.052526921 | R31: =IF($M31="","",$M31*Assumptions!$B$7) -> 55 | S31: =IF(OR($J31="",$Q31="",$Q31=0),"",($J31+$R31)/($Q31*(1-Assumptions!$B$4))) -> 1855.9531 | T31: =IF(OR($K31="",$S31="",$S31=0),"",$K31/$S31) | U31: =IF(OR($K31="",$Q31=""),"",MAX(0,($K31-MAX($K31*Assumptions!$B$4,Assumptions!$B$5))*$Q31-$R31)) | V31: =IF($A31="","",IF($O31="FAIL","REJECT",IF($J31="","NEEDS PRICE",IF(OR($K31="",$L31=""),"NEEDS VALUATION",IF($T31>=Assumptions!$B$13,"BUY",IF($T31>=1,"MARGINAL","PASS")))))) -> NEEDS VALUATION | W31: Available - reg | X31: [T2] 'ag' reads as ambiguous when spoken. Weak radio test.
A32: minefinancing.com | B32: =IF($A32="","",IF(ISERROR(FIND(".",$A32)),"",LOWER(MID($A32,FIND(CHAR(1),SUBSTITUTE($A32,".",CHAR(1),LEN($A32)-LEN(SUBSTITUTE($A32,".",""))))+1,LEN($A32))))) -> com | C32: =IF($B32="","",IFERROR(INDEX(Rubric!$B$14:$B$23,MATCH($B32,Rubric!$A$14:$A$23,0)),INDEX(Rubric!$B$14:$B$23,MATCH("other",Rubric!$A$14:$A$23,0)))) -> 5 | D32: 3 | E32: 2 | F32: 4 | G32: 3 | H32: N | I32: N | J32: 22.99 | M32: =IF($B32="","",IFERROR(INDEX(Rubric!$C$14:$C$23,MATCH($B32,Rubric!$A$14:$A$23,0)),INDEX(Rubric!$C$14:$C$23,MATCH("other",Rubric!$A$14:$A$23,0)))) -> 11 | N32: =IF(OR($A32="",$C32=""),"",$C32*Rubric!$B$5+$D32*Rubric!$B$6+$E32*Rubric!$B$7+$F32*Rubric!$B$8+$G32*Rubric!$B$9) -> 3.38 | O32: =IF($A32="","",IF(OR(UPPER($H32)="Y",UPPER($I32)="Y"),"FAIL","PASS")) -> PASS | P32: =IF($N32="","",Assumptions!$B$6*MAX(0.05,($N32/Assumptions!$B$11)^Assumptions!$B$12)) -> 0.011266667 | Q32: =IF($P32="","",1-(1-$P32)^Assumptions!$B$7) -> 0.055078177 | R32: =IF($M32="","",$M32*Assumptions!$B$7) -> 55 | S32: =IF(OR($J32="",$Q32="",$Q32=0),"",($J32+$R32)/($Q32*(1-Assumptions!$B$4))) -> 1769.9842 | T32: =IF(OR($K32="",$S32="",$S32=0),"",$K32/$S32) | U32: =IF(OR($K32="",$Q32=""),"",MAX(0,($K32-MAX($K32*Assumptions!$B$4,Assumptions!$B$5))*$Q32-$R32)) | V32: =IF($A32="","",IF($O32="FAIL","REJECT",IF($J32="","NEEDS PRICE",IF(OR($K32="",$L32=""),"NEEDS VALUATION",IF($T32>=Assumptions!$B$13,"BUY",IF($T32>=1,"MARGINAL","PASS")))))) -> NEEDS VALUATION | W32: Available - reg | X32: [T2] Mining equipment. 'mine' is a homophone trap.
A33: equipmentcapital.com | B33: =IF($A33="","",IF(ISERROR(FIND(".",$A33)),"",LOWER(MID($A33,FIND(CHAR(1),SUBSTITUTE($A33,".",CHAR(1),LEN($A33)-LEN(SUBSTITUTE($A33,".",""))))+1,LEN($A33))))) -> com | C33: =IF($B33="","",IFERROR(INDEX(Rubric!$B$14:$B$23,MATCH($B33,Rubric!$A$14:$A$23,0)),INDEX(Rubric!$B$14:$B$23,MATCH("other",Rubric!$A$14:$A$23,0)))) -> 5 | D33: 5 | E33: 3 | F33: 4 | G33: 5 | H33: N | I33: N | M33: =IF($B33="","",IFERROR(INDEX(Rubric!$C$14:$C$23,MATCH($B33,Rubric!$A$14:$A$23,0)),INDEX(Rubric!$C$14:$C$23,MATCH("other",Rubric!$A$14:$A$23,0)))) -> 11 | N33: =IF(OR($A33="",$C33=""),"",$C33*Rubric!$B$5+$D33*Rubric!$B$6+$E33*Rubric!$B$7+$F33*Rubric!$B$8+$G33*Rubric!$B$9) -> 4.4 | O33: =IF($A33="","",IF(OR(UPPER($H33)="Y",UPPER($I33)="Y"),"FAIL","PASS")) -> PASS | P33: =IF($N33="","",Assumptions!$B$6*MAX(0.05,($N33/Assumptions!$B$11)^Assumptions!$B$12)) -> 0.014666667 | Q33: =IF($P33="","",1-(1-$P33)^Assumptions!$B$7) -> 0.071213541 | R33: =IF($M33="","",$M33*Assumptions!$B$7) -> 55 | S33: =IF(OR($J33="",$Q33="",$Q33=0),"",($J33+$R33)/($Q33*(1-Assumptions!$B$4))) | T33: =IF(OR($K33="",$S33="",$S33=0),"",$K33/$S33) | U33: =IF(OR($K33="",$Q33=""),"",MAX(0,($K33-MAX($K33*Assumptions!$B$4,Assumptions!$B$5))*$Q33-$R33)) | V33: =IF($A33="","",IF($O33="FAIL","REJECT",IF($J33="","NEEDS PRICE",IF(OR($K33="",$L33=""),"NEEDS VALUATION",IF($T33>=Assumptions!$B$13,"BUY",IF($T33>=1,"MARGINAL","PASS")))))) -> NEEDS PRICE | W33: Taken | X33: [T3] Reads like a lender's own name — strong end-user appeal.
A34: equipmentfunding.com | B34: =IF($A34="","",IF(ISERROR(FIND(".",$A34)),"",LOWER(MID($A34,FIND(CHAR(1),SUBSTITUTE($A34,".",CHAR(1),LEN($A34)-LEN(SUBSTITUTE($A34,".",""))))+1,LEN($A34))))) -> com | C34: =IF($B34="","",IFERROR(INDEX(Rubric!$B$14:$B$23,MATCH($B34,Rubric!$A$14:$A$23,0)),INDEX(Rubric!$B$14:$B$23,MATCH("other",Rubric!$A$14:$A$23,0)))) -> 5 | D34: 5 | E34: 3 | F34: 4 | G34: 5 | H34: N | I34: N | M34: =IF($B34="","",IFERROR(INDEX(Rubric!$C$14:$C$23,MATCH($B34,Rubric!$A$14:$A$23,0)),INDEX(Rubric!$C$14:$C$23,MATCH("other",Rubric!$A$14:$A$23,0)))) -> 11 | N34: =IF(OR($A34="",$C34=""),"",$C34*Rubric!$B$5+$D34*Rubric!$B$6+$E34*Rubric!$B$7+$F34*Rubric!$B$8+$G34*Rubric!$B$9) -> 4.4 | O34: =IF($A34="","",IF(OR(UPPER($H34)="Y",UPPER($I34)="Y"),"FAIL","PASS")) -> PASS | P34: =IF($N34="","",Assumptions!$B$6*MAX(0.05,($N34/Assumptions!$B$11)^Assumptions!$B$12)) -> 0.014666667 | Q34: =IF($P34="","",1-(1-$P34)^Assumptions!$B$7) -> 0.071213541 | R34: =IF($M34="","",$M34*Assumptions!$B$7) -> 55 | S34: =IF(OR($J34="",$Q34="",$Q34=0),"",($J34+$R34)/($Q34*(1-Assumptions!$B$4))) | T34: =IF(OR($K34="",$S34="",$S34=0),"",$K34/$S34) | U34: =IF(OR($K34="",$Q34=""),"",MAX(0,($K34-MAX($K34*Assumptions!$B$4,Assumptions!$B$5))*$Q34-$R34)) | V34: =IF($A34="","",IF($O34="FAIL","REJECT",IF($J34="","NEEDS PRICE",IF(OR($K34="",$L34=""),"NEEDS VALUATION",IF($T34>=Assumptions!$B$13,"BUY",IF($T34>=1,"MARGINAL","PASS")))))) -> NEEDS PRICE | W34: Taken | X34: [T3] Same pattern as above.
A35: equipmentlending.com | B35: =IF($A35="","",IF(ISERROR(FIND(".",$A35)),"",LOWER(MID($A35,FIND(CHAR(1),SUBSTITUTE($A35,".",CHAR(1),LEN($A35)-LEN(SUBSTITUTE($A35,".",""))))+1,LEN($A35))))) -> com | C35: =IF($B35="","",IFERROR(INDEX(Rubric!$B$14:$B$23,MATCH($B35,Rubric!$A$14:$A$23,0)),INDEX(Rubric!$B$14:$B$23,MATCH("other",Rubric!$A$14:$A$23,0)))) -> 5 | D35: 5 | E35: 3 | F35: 4 | G35: 5 | H35: N | I35: N | M35: =IF($B35="","",IFERROR(INDEX(Rubric!$C$14:$C$23,MATCH($B35,Rubric!$A$14:$A$23,0)),INDEX(Rubric!$C$14:$C$23,MATCH("other",Rubric!$A$14:$A$23,0)))) -> 11 | N35: =IF(OR($A35="",$C35=""),"",$C35*Rubric!$B$5+$D35*Rubric!$B$6+$E35*Rubric!$B$7+$F35*Rubric!$B$8+$G35*Rubric!$B$9) -> 4.4 | O35: =IF($A35="","",IF(OR(UPPER($H35)="Y",UPPER($I35)="Y"),"FAIL","PASS")) -> PASS | P35: =IF($N35="","",Assumptions!$B$6*MAX(0.05,($N35/Assumptions!$B$11)^Assumptions!$B$12)) -> 0.014666667 | Q35: =IF($P35="","",1-(1-$P35)^Assumptions!$B$7) -> 0.071213541 | R35: =IF($M35="","",$M35*Assumptions!$B$7) -> 55 | S35: =IF(OR($J35="",$Q35="",$Q35=0),"",($J35+$R35)/($Q35*(1-Assumptions!$B$4))) | T35: =IF(OR($K35="",$S35="",$S35=0),"",$K35/$S35) | U35: =IF(OR($K35="",$Q35=""),"",MAX(0,($K35-MAX($K35*Assumptions!$B$4,Assumptions!$B$5))*$Q35-$R35)) | V35: =IF($A35="","",IF($O35="FAIL","REJECT",IF($J35="","NEEDS PRICE",IF(OR($K35="",$L35=""),"NEEDS VALUATION",IF($T35>=Assumptions!$B$13,"BUY",IF($T35>=1,"MARGINAL","PASS")))))) -> NEEDS PRICE | W35: Taken | X35: [T3] Same pattern as above.
A36: leasingcapital.com | B36: =IF($A36="","",IF(ISERROR(FIND(".",$A36)),"",LOWER(MID($A36,FIND(CHAR(1),SUBSTITUTE($A36,".",CHAR(1),LEN($A36)-LEN(SUBSTITUTE($A36,".",""))))+1,LEN($A36))))) -> com | C36: =IF($B36="","",IFERROR(INDEX(Rubric!$B$14:$B$23,MATCH($B36,Rubric!$A$14:$A$23,0)),INDEX(Rubric!$B$14:$B$23,MATCH("other",Rubric!$A$14:$A$23,0)))) -> 5 | D36: 4 | E36: 3 | F36: 4 | G36: 5 | H36: N | I36: N | J36: 6495 | M36: =IF($B36="","",IFERROR(INDEX(Rubric!$C$14:$C$23,MATCH($B36,Rubric!$A$14:$A$23,0)),INDEX(Rubric!$C$14:$C$23,MATCH("other",Rubric!$A$14:$A$23,0)))) -> 11 | N36: =IF(OR($A36="",$C36=""),"",$C36*Rubric!$B$5+$D36*Rubric!$B$6+$E36*Rubric!$B$7+$F36*Rubric!$B$8+$G36*Rubric!$B$9) -> 4.1 | O36: =IF($A36="","",IF(OR(UPPER($H36)="Y",UPPER($I36)="Y"),"FAIL","PASS")) -> PASS | P36: =IF($N36="","",Assumptions!$B$6*MAX(0.05,($N36/Assumptions!$B$11)^Assumptions!$B$12)) -> 0.013666667 | Q36: =IF($P36="","",1-(1-$P36)^Assumptions!$B$7) -> 0.066490908 | R36: =IF($M36="","",$M36*Assumptions!$B$7) -> 55 | S36: =IF(OR($J36="",$Q36="",$Q36=0),"",($J36+$R36)/($Q36*(1-Assumptions!$B$4))) -> 123137.14 | T36: =IF(OR($K36="",$S36="",$S36=0),"",$K36/$S36) | U36: =IF(OR($K36="",$Q36=""),"",MAX(0,($K36-MAX($K36*Assumptions!$B$4,Assumptions!$B$5))*$Q36-$R36)) | V36: =IF($A36="","",IF($O36="FAIL","REJECT",IF($J36="","NEEDS PRICE",IF(OR($K36="",$L36=""),"NEEDS VALUATION",IF($T36>=Assumptions!$B$13,"BUY",IF($T36>=1,"MARGINAL","PASS")))))) -> NEEDS VALUATION | W36: Available - premium | X36: [T3] Generic enough to suit many lessors.
